[2017-08-04 09:39:13]: 
Traceback (most recent call last):
  File "/Users/qianlong/Documents/Workspace/PyCharmProjects/xywy_ask_answer/database/RabbitMQ.py", line 104, in __init__
    self.connection = pika.BlockingConnection(connection_parameter)
  File "/Users/qianlong/Documents/Applications/Anaconda2/anaconda/lib/python2.7/site-packages/pika/adapters/blocking_connection.py", line 339, in __init__
    self._process_io_for_connection_setup()
  File "/Users/qianlong/Documents/Applications/Anaconda2/anaconda/lib/python2.7/site-packages/pika/adapters/blocking_connection.py", line 374, in _process_io_for_connection_setup
    self._open_error_result.is_ready)
  File "/Users/qianlong/Documents/Applications/Anaconda2/anaconda/lib/python2.7/site-packages/pika/adapters/blocking_connection.py", line 395, in _flush_output
    raise exceptions.ConnectionClosed()
ConnectionClosed
 
[2017-08-04 09:39:13]: 
Traceback (most recent call last):
  File "/Users/qianlong/Documents/Workspace/PyCharmProjects/xywy_ask_answer/database/RabbitMQ.py", line 104, in __init__
    self.connection = pika.BlockingConnection(connection_parameter)
  File "/Users/qianlong/Documents/Applications/Anaconda2/anaconda/lib/python2.7/site-packages/pika/adapters/blocking_connection.py", line 339, in __init__
    self._process_io_for_connection_setup()
  File "/Users/qianlong/Documents/Applications/Anaconda2/anaconda/lib/python2.7/site-packages/pika/adapters/blocking_connection.py", line 374, in _process_io_for_connection_setup
    self._open_error_result.is_ready)
  File "/Users/qianlong/Documents/Applications/Anaconda2/anaconda/lib/python2.7/site-packages/pika/adapters/blocking_connection.py", line 395, in _flush_output
    raise exceptions.ConnectionClosed()
ConnectionClosed
 
[2017-08-04 09:39:13]: 
Traceback (most recent call last):
  File "/Users/qianlong/Documents/Workspace/PyCharmProjects/xywy_ask_answer/database/RabbitMQ.py", line 104, in __init__
    self.connection = pika.BlockingConnection(connection_parameter)
  File "/Users/qianlong/Documents/Applications/Anaconda2/anaconda/lib/python2.7/site-packages/pika/adapters/blocking_connection.py", line 339, in __init__
    self._process_io_for_connection_setup()
  File "/Users/qianlong/Documents/Applications/Anaconda2/anaconda/lib/python2.7/site-packages/pika/adapters/blocking_connection.py", line 374, in _process_io_for_connection_setup
    self._open_error_result.is_ready)
  File "/Users/qianlong/Documents/Applications/Anaconda2/anaconda/lib/python2.7/site-packages/pika/adapters/blocking_connection.py", line 395, in _flush_output
    raise exceptions.ConnectionClosed()
ConnectionClosed
 
[2017-08-04 09:39:14]: 
Traceback (most recent call last):
  File "/Users/qianlong/Documents/Workspace/PyCharmProjects/xywy_ask_answer/database/RabbitMQ.py", line 104, in __init__
    self.connection = pika.BlockingConnection(connection_parameter)
  File "/Users/qianlong/Documents/Applications/Anaconda2/anaconda/lib/python2.7/site-packages/pika/adapters/blocking_connection.py", line 339, in __init__
    self._process_io_for_connection_setup()
  File "/Users/qianlong/Documents/Applications/Anaconda2/anaconda/lib/python2.7/site-packages/pika/adapters/blocking_connection.py", line 374, in _process_io_for_connection_setup
    self._open_error_result.is_ready)
  File "/Users/qianlong/Documents/Applications/Anaconda2/anaconda/lib/python2.7/site-packages/pika/adapters/blocking_connection.py", line 395, in _flush_output
    raise exceptions.ConnectionClosed()
ConnectionClosed
 
[2017-08-04 09:39:14]: 
Traceback (most recent call last):
  File "/Users/qianlong/Documents/Workspace/PyCharmProjects/xywy_ask_answer/database/RabbitMQ.py", line 104, in __init__
    self.connection = pika.BlockingConnection(connection_parameter)
  File "/Users/qianlong/Documents/Applications/Anaconda2/anaconda/lib/python2.7/site-packages/pika/adapters/blocking_connection.py", line 339, in __init__
    self._process_io_for_connection_setup()
  File "/Users/qianlong/Documents/Applications/Anaconda2/anaconda/lib/python2.7/site-packages/pika/adapters/blocking_connection.py", line 374, in _process_io_for_connection_setup
    self._open_error_result.is_ready)
  File "/Users/qianlong/Documents/Applications/Anaconda2/anaconda/lib/python2.7/site-packages/pika/adapters/blocking_connection.py", line 395, in _flush_output
    raise exceptions.ConnectionClosed()
ConnectionClosed
 
[2017-08-04 09:39:14]: 
Traceback (most recent call last):
  File "/Users/qianlong/Documents/Workspace/PyCharmProjects/xywy_ask_answer/database/RabbitMQ.py", line 104, in __init__
    self.connection = pika.BlockingConnection(connection_parameter)
  File "/Users/qianlong/Documents/Applications/Anaconda2/anaconda/lib/python2.7/site-packages/pika/adapters/blocking_connection.py", line 339, in __init__
    self._process_io_for_connection_setup()
  File "/Users/qianlong/Documents/Applications/Anaconda2/anaconda/lib/python2.7/site-packages/pika/adapters/blocking_connection.py", line 374, in _process_io_for_connection_setup
    self._open_error_result.is_ready)
  File "/Users/qianlong/Documents/Applications/Anaconda2/anaconda/lib/python2.7/site-packages/pika/adapters/blocking_connection.py", line 395, in _flush_output
    raise exceptions.ConnectionClosed()
ConnectionClosed
 
[2017-08-04 09:39:14]: 
Traceback (most recent call last):
  File "/Users/qianlong/Documents/Workspace/PyCharmProjects/xywy_ask_answer/database/RabbitMQ.py", line 104, in __init__
    self.connection = pika.BlockingConnection(connection_parameter)
  File "/Users/qianlong/Documents/Applications/Anaconda2/anaconda/lib/python2.7/site-packages/pika/adapters/blocking_connection.py", line 339, in __init__
    self._process_io_for_connection_setup()
  File "/Users/qianlong/Documents/Applications/Anaconda2/anaconda/lib/python2.7/site-packages/pika/adapters/blocking_connection.py", line 374, in _process_io_for_connection_setup
    self._open_error_result.is_ready)
  File "/Users/qianlong/Documents/Applications/Anaconda2/anaconda/lib/python2.7/site-packages/pika/adapters/blocking_connection.py", line 395, in _flush_output
    raise exceptions.ConnectionClosed()
ConnectionClosed
 
[2017-08-04 09:39:15]: 
Traceback (most recent call last):
  File "/Users/qianlong/Documents/Workspace/PyCharmProjects/xywy_ask_answer/database/RabbitMQ.py", line 104, in __init__
    self.connection = pika.BlockingConnection(connection_parameter)
  File "/Users/qianlong/Documents/Applications/Anaconda2/anaconda/lib/python2.7/site-packages/pika/adapters/blocking_connection.py", line 339, in __init__
    self._process_io_for_connection_setup()
  File "/Users/qianlong/Documents/Applications/Anaconda2/anaconda/lib/python2.7/site-packages/pika/adapters/blocking_connection.py", line 374, in _process_io_for_connection_setup
    self._open_error_result.is_ready)
  File "/Users/qianlong/Documents/Applications/Anaconda2/anaconda/lib/python2.7/site-packages/pika/adapters/blocking_connection.py", line 395, in _flush_output
    raise exceptions.ConnectionClosed()
ConnectionClosed
 
[2017-08-04 09:39:15]: 
Traceback (most recent call last):
  File "/Users/qianlong/Documents/Workspace/PyCharmProjects/xywy_ask_answer/database/RabbitMQ.py", line 104, in __init__
    self.connection = pika.BlockingConnection(connection_parameter)
  File "/Users/qianlong/Documents/Applications/Anaconda2/anaconda/lib/python2.7/site-packages/pika/adapters/blocking_connection.py", line 339, in __init__
    self._process_io_for_connection_setup()
  File "/Users/qianlong/Documents/Applications/Anaconda2/anaconda/lib/python2.7/site-packages/pika/adapters/blocking_connection.py", line 374, in _process_io_for_connection_setup
    self._open_error_result.is_ready)
  File "/Users/qianlong/Documents/Applications/Anaconda2/anaconda/lib/python2.7/site-packages/pika/adapters/blocking_connection.py", line 395, in _flush_output
    raise exceptions.ConnectionClosed()
ConnectionClosed
 
[2017-08-04 09:39:15]: 
Traceback (most recent call last):
  File "/Users/qianlong/Documents/Workspace/PyCharmProjects/xywy_ask_answer/database/RabbitMQ.py", line 104, in __init__
    self.connection = pika.BlockingConnection(connection_parameter)
  File "/Users/qianlong/Documents/Applications/Anaconda2/anaconda/lib/python2.7/site-packages/pika/adapters/blocking_connection.py", line 339, in __init__
    self._process_io_for_connection_setup()
  File "/Users/qianlong/Documents/Applications/Anaconda2/anaconda/lib/python2.7/site-packages/pika/adapters/blocking_connection.py", line 374, in _process_io_for_connection_setup
    self._open_error_result.is_ready)
  File "/Users/qianlong/Documents/Applications/Anaconda2/anaconda/lib/python2.7/site-packages/pika/adapters/blocking_connection.py", line 395, in _flush_output
    raise exceptions.ConnectionClosed()
ConnectionClosed
 
[2017-08-04 09:39:15]: 
Traceback (most recent call last):
  File "/Users/qianlong/Documents/Workspace/PyCharmProjects/xywy_ask_answer/database/RabbitMQ.py", line 104, in __init__
    self.connection = pika.BlockingConnection(connection_parameter)
  File "/Users/qianlong/Documents/Applications/Anaconda2/anaconda/lib/python2.7/site-packages/pika/adapters/blocking_connection.py", line 339, in __init__
    self._process_io_for_connection_setup()
  File "/Users/qianlong/Documents/Applications/Anaconda2/anaconda/lib/python2.7/site-packages/pika/adapters/blocking_connection.py", line 374, in _process_io_for_connection_setup
    self._open_error_result.is_ready)
  File "/Users/qianlong/Documents/Applications/Anaconda2/anaconda/lib/python2.7/site-packages/pika/adapters/blocking_connection.py", line 395, in _flush_output
    raise exceptions.ConnectionClosed()
ConnectionClosed
 
[2017-08-04 09:39:16]: 
Traceback (most recent call last):
  File "/Users/qianlong/Documents/Workspace/PyCharmProjects/xywy_ask_answer/database/RabbitMQ.py", line 104, in __init__
    self.connection = pika.BlockingConnection(connection_parameter)
  File "/Users/qianlong/Documents/Applications/Anaconda2/anaconda/lib/python2.7/site-packages/pika/adapters/blocking_connection.py", line 339, in __init__
    self._process_io_for_connection_setup()
  File "/Users/qianlong/Documents/Applications/Anaconda2/anaconda/lib/python2.7/site-packages/pika/adapters/blocking_connection.py", line 374, in _process_io_for_connection_setup
    self._open_error_result.is_ready)
  File "/Users/qianlong/Documents/Applications/Anaconda2/anaconda/lib/python2.7/site-packages/pika/adapters/blocking_connection.py", line 395, in _flush_output
    raise exceptions.ConnectionClosed()
ConnectionClosed
 
[2017-08-04 09:39:16]: 
Traceback (most recent call last):
  File "/Users/qianlong/Documents/Workspace/PyCharmProjects/xywy_ask_answer/database/RabbitMQ.py", line 104, in __init__
    self.connection = pika.BlockingConnection(connection_parameter)
  File "/Users/qianlong/Documents/Applications/Anaconda2/anaconda/lib/python2.7/site-packages/pika/adapters/blocking_connection.py", line 339, in __init__
    self._process_io_for_connection_setup()
  File "/Users/qianlong/Documents/Applications/Anaconda2/anaconda/lib/python2.7/site-packages/pika/adapters/blocking_connection.py", line 374, in _process_io_for_connection_setup
    self._open_error_result.is_ready)
  File "/Users/qianlong/Documents/Applications/Anaconda2/anaconda/lib/python2.7/site-packages/pika/adapters/blocking_connection.py", line 395, in _flush_output
    raise exceptions.ConnectionClosed()
ConnectionClosed
 
[2017-08-04 09:39:16]: 
Traceback (most recent call last):
  File "/Users/qianlong/Documents/Workspace/PyCharmProjects/xywy_ask_answer/database/RabbitMQ.py", line 104, in __init__
    self.connection = pika.BlockingConnection(connection_parameter)
  File "/Users/qianlong/Documents/Applications/Anaconda2/anaconda/lib/python2.7/site-packages/pika/adapters/blocking_connection.py", line 339, in __init__
    self._process_io_for_connection_setup()
  File "/Users/qianlong/Documents/Applications/Anaconda2/anaconda/lib/python2.7/site-packages/pika/adapters/blocking_connection.py", line 374, in _process_io_for_connection_setup
    self._open_error_result.is_ready)
  File "/Users/qianlong/Documents/Applications/Anaconda2/anaconda/lib/python2.7/site-packages/pika/adapters/blocking_connection.py", line 395, in _flush_output
    raise exceptions.ConnectionClosed()
ConnectionClosed
 
[2017-08-04 09:39:17]: 
Traceback (most recent call last):
  File "/Users/qianlong/Documents/Workspace/PyCharmProjects/xywy_ask_answer/database/RabbitMQ.py", line 104, in __init__
    self.connection = pika.BlockingConnection(connection_parameter)
  File "/Users/qianlong/Documents/Applications/Anaconda2/anaconda/lib/python2.7/site-packages/pika/adapters/blocking_connection.py", line 339, in __init__
    self._process_io_for_connection_setup()
  File "/Users/qianlong/Documents/Applications/Anaconda2/anaconda/lib/python2.7/site-packages/pika/adapters/blocking_connection.py", line 374, in _process_io_for_connection_setup
    self._open_error_result.is_ready)
  File "/Users/qianlong/Documents/Applications/Anaconda2/anaconda/lib/python2.7/site-packages/pika/adapters/blocking_connection.py", line 395, in _flush_output
    raise exceptions.ConnectionClosed()
ConnectionClosed
 
[2017-08-04 09:39:17]: 
Traceback (most recent call last):
  File "/Users/qianlong/Documents/Workspace/PyCharmProjects/xywy_ask_answer/database/RabbitMQ.py", line 104, in __init__
    self.connection = pika.BlockingConnection(connection_parameter)
  File "/Users/qianlong/Documents/Applications/Anaconda2/anaconda/lib/python2.7/site-packages/pika/adapters/blocking_connection.py", line 339, in __init__
    self._process_io_for_connection_setup()
  File "/Users/qianlong/Documents/Applications/Anaconda2/anaconda/lib/python2.7/site-packages/pika/adapters/blocking_connection.py", line 374, in _process_io_for_connection_setup
    self._open_error_result.is_ready)
  File "/Users/qianlong/Documents/Applications/Anaconda2/anaconda/lib/python2.7/site-packages/pika/adapters/blocking_connection.py", line 395, in _flush_output
    raise exceptions.ConnectionClosed()
ConnectionClosed
 
[2017-08-04 09:39:17]: 
Traceback (most recent call last):
  File "/Users/qianlong/Documents/Workspace/PyCharmProjects/xywy_ask_answer/database/RabbitMQ.py", line 104, in __init__
    self.connection = pika.BlockingConnection(connection_parameter)
  File "/Users/qianlong/Documents/Applications/Anaconda2/anaconda/lib/python2.7/site-packages/pika/adapters/blocking_connection.py", line 339, in __init__
    self._process_io_for_connection_setup()
  File "/Users/qianlong/Documents/Applications/Anaconda2/anaconda/lib/python2.7/site-packages/pika/adapters/blocking_connection.py", line 374, in _process_io_for_connection_setup
    self._open_error_result.is_ready)
  File "/Users/qianlong/Documents/Applications/Anaconda2/anaconda/lib/python2.7/site-packages/pika/adapters/blocking_connection.py", line 395, in _flush_output
    raise exceptions.ConnectionClosed()
ConnectionClosed
 
[2017-08-04 09:39:17]: 
Traceback (most recent call last):
  File "/Users/qianlong/Documents/Workspace/PyCharmProjects/xywy_ask_answer/database/RabbitMQ.py", line 104, in __init__
    self.connection = pika.BlockingConnection(connection_parameter)
  File "/Users/qianlong/Documents/Applications/Anaconda2/anaconda/lib/python2.7/site-packages/pika/adapters/blocking_connection.py", line 339, in __init__
    self._process_io_for_connection_setup()
  File "/Users/qianlong/Documents/Applications/Anaconda2/anaconda/lib/python2.7/site-packages/pika/adapters/blocking_connection.py", line 374, in _process_io_for_connection_setup
    self._open_error_result.is_ready)
  File "/Users/qianlong/Documents/Applications/Anaconda2/anaconda/lib/python2.7/site-packages/pika/adapters/blocking_connection.py", line 395, in _flush_output
    raise exceptions.ConnectionClosed()
ConnectionClosed
 
[2017-08-04 09:39:18]: 
Traceback (most recent call last):
  File "/Users/qianlong/Documents/Workspace/PyCharmProjects/xywy_ask_answer/database/RabbitMQ.py", line 104, in __init__
    self.connection = pika.BlockingConnection(connection_parameter)
  File "/Users/qianlong/Documents/Applications/Anaconda2/anaconda/lib/python2.7/site-packages/pika/adapters/blocking_connection.py", line 339, in __init__
    self._process_io_for_connection_setup()
  File "/Users/qianlong/Documents/Applications/Anaconda2/anaconda/lib/python2.7/site-packages/pika/adapters/blocking_connection.py", line 374, in _process_io_for_connection_setup
    self._open_error_result.is_ready)
  File "/Users/qianlong/Documents/Applications/Anaconda2/anaconda/lib/python2.7/site-packages/pika/adapters/blocking_connection.py", line 395, in _flush_output
    raise exceptions.ConnectionClosed()
ConnectionClosed
 
[2017-08-04 09:39:18]: 
Traceback (most recent call last):
  File "/Users/qianlong/Documents/Workspace/PyCharmProjects/xywy_ask_answer/database/RabbitMQ.py", line 104, in __init__
    self.connection = pika.BlockingConnection(connection_parameter)
  File "/Users/qianlong/Documents/Applications/Anaconda2/anaconda/lib/python2.7/site-packages/pika/adapters/blocking_connection.py", line 339, in __init__
    self._process_io_for_connection_setup()
  File "/Users/qianlong/Documents/Applications/Anaconda2/anaconda/lib/python2.7/site-packages/pika/adapters/blocking_connection.py", line 374, in _process_io_for_connection_setup
    self._open_error_result.is_ready)
  File "/Users/qianlong/Documents/Applications/Anaconda2/anaconda/lib/python2.7/site-packages/pika/adapters/blocking_connection.py", line 395, in _flush_output
    raise exceptions.ConnectionClosed()
ConnectionClosed
 
[2017-08-04 09:39:18]: 
Traceback (most recent call last):
  File "/Users/qianlong/Documents/Workspace/PyCharmProjects/xywy_ask_answer/database/RabbitMQ.py", line 104, in __init__
    self.connection = pika.BlockingConnection(connection_parameter)
  File "/Users/qianlong/Documents/Applications/Anaconda2/anaconda/lib/python2.7/site-packages/pika/adapters/blocking_connection.py", line 339, in __init__
    self._process_io_for_connection_setup()
  File "/Users/qianlong/Documents/Applications/Anaconda2/anaconda/lib/python2.7/site-packages/pika/adapters/blocking_connection.py", line 374, in _process_io_for_connection_setup
    self._open_error_result.is_ready)
  File "/Users/qianlong/Documents/Applications/Anaconda2/anaconda/lib/python2.7/site-packages/pika/adapters/blocking_connection.py", line 395, in _flush_output
    raise exceptions.ConnectionClosed()
ConnectionClosed
 
[2017-08-04 09:39:18]: 
Traceback (most recent call last):
  File "/Users/qianlong/Documents/Workspace/PyCharmProjects/xywy_ask_answer/database/RabbitMQ.py", line 104, in __init__
    self.connection = pika.BlockingConnection(connection_parameter)
  File "/Users/qianlong/Documents/Applications/Anaconda2/anaconda/lib/python2.7/site-packages/pika/adapters/blocking_connection.py", line 339, in __init__
    self._process_io_for_connection_setup()
  File "/Users/qianlong/Documents/Applications/Anaconda2/anaconda/lib/python2.7/site-packages/pika/adapters/blocking_connection.py", line 374, in _process_io_for_connection_setup
    self._open_error_result.is_ready)
  File "/Users/qianlong/Documents/Applications/Anaconda2/anaconda/lib/python2.7/site-packages/pika/adapters/blocking_connection.py", line 395, in _flush_output
    raise exceptions.ConnectionClosed()
ConnectionClosed
 
[2017-08-04 09:39:19]: 
Traceback (most recent call last):
  File "/Users/qianlong/Documents/Workspace/PyCharmProjects/xywy_ask_answer/database/RabbitMQ.py", line 104, in __init__
    self.connection = pika.BlockingConnection(connection_parameter)
  File "/Users/qianlong/Documents/Applications/Anaconda2/anaconda/lib/python2.7/site-packages/pika/adapters/blocking_connection.py", line 339, in __init__
    self._process_io_for_connection_setup()
  File "/Users/qianlong/Documents/Applications/Anaconda2/anaconda/lib/python2.7/site-packages/pika/adapters/blocking_connection.py", line 374, in _process_io_for_connection_setup
    self._open_error_result.is_ready)
  File "/Users/qianlong/Documents/Applications/Anaconda2/anaconda/lib/python2.7/site-packages/pika/adapters/blocking_connection.py", line 395, in _flush_output
    raise exceptions.ConnectionClosed()
ConnectionClosed
 
[2017-08-04 09:39:19]: 
Traceback (most recent call last):
  File "/Users/qianlong/Documents/Workspace/PyCharmProjects/xywy_ask_answer/database/RabbitMQ.py", line 104, in __init__
    self.connection = pika.BlockingConnection(connection_parameter)
  File "/Users/qianlong/Documents/Applications/Anaconda2/anaconda/lib/python2.7/site-packages/pika/adapters/blocking_connection.py", line 339, in __init__
    self._process_io_for_connection_setup()
  File "/Users/qianlong/Documents/Applications/Anaconda2/anaconda/lib/python2.7/site-packages/pika/adapters/blocking_connection.py", line 374, in _process_io_for_connection_setup
    self._open_error_result.is_ready)
  File "/Users/qianlong/Documents/Applications/Anaconda2/anaconda/lib/python2.7/site-packages/pika/adapters/blocking_connection.py", line 395, in _flush_output
    raise exceptions.ConnectionClosed()
ConnectionClosed
 
[2017-08-04 09:39:19]: 
Traceback (most recent call last):
  File "/Users/qianlong/Documents/Workspace/PyCharmProjects/xywy_ask_answer/database/RabbitMQ.py", line 104, in __init__
    self.connection = pika.BlockingConnection(connection_parameter)
  File "/Users/qianlong/Documents/Applications/Anaconda2/anaconda/lib/python2.7/site-packages/pika/adapters/blocking_connection.py", line 339, in __init__
    self._process_io_for_connection_setup()
  File "/Users/qianlong/Documents/Applications/Anaconda2/anaconda/lib/python2.7/site-packages/pika/adapters/blocking_connection.py", line 374, in _process_io_for_connection_setup
    self._open_error_result.is_ready)
  File "/Users/qianlong/Documents/Applications/Anaconda2/anaconda/lib/python2.7/site-packages/pika/adapters/blocking_connection.py", line 395, in _flush_output
    raise exceptions.ConnectionClosed()
ConnectionClosed
 
[2017-08-04 09:39:19]: 
Traceback (most recent call last):
  File "/Users/qianlong/Documents/Workspace/PyCharmProjects/xywy_ask_answer/database/RabbitMQ.py", line 104, in __init__
    self.connection = pika.BlockingConnection(connection_parameter)
  File "/Users/qianlong/Documents/Applications/Anaconda2/anaconda/lib/python2.7/site-packages/pika/adapters/blocking_connection.py", line 339, in __init__
    self._process_io_for_connection_setup()
  File "/Users/qianlong/Documents/Applications/Anaconda2/anaconda/lib/python2.7/site-packages/pika/adapters/blocking_connection.py", line 374, in _process_io_for_connection_setup
    self._open_error_result.is_ready)
  File "/Users/qianlong/Documents/Applications/Anaconda2/anaconda/lib/python2.7/site-packages/pika/adapters/blocking_connection.py", line 395, in _flush_output
    raise exceptions.ConnectionClosed()
ConnectionClosed
 
[2017-08-04 09:39:20]: 
Traceback (most recent call last):
  File "/Users/qianlong/Documents/Workspace/PyCharmProjects/xywy_ask_answer/database/RabbitMQ.py", line 104, in __init__
    self.connection = pika.BlockingConnection(connection_parameter)
  File "/Users/qianlong/Documents/Applications/Anaconda2/anaconda/lib/python2.7/site-packages/pika/adapters/blocking_connection.py", line 339, in __init__
    self._process_io_for_connection_setup()
  File "/Users/qianlong/Documents/Applications/Anaconda2/anaconda/lib/python2.7/site-packages/pika/adapters/blocking_connection.py", line 374, in _process_io_for_connection_setup
    self._open_error_result.is_ready)
  File "/Users/qianlong/Documents/Applications/Anaconda2/anaconda/lib/python2.7/site-packages/pika/adapters/blocking_connection.py", line 395, in _flush_output
    raise exceptions.ConnectionClosed()
ConnectionClosed
 
[2017-08-04 09:39:20]: 
Traceback (most recent call last):
  File "/Users/qianlong/Documents/Workspace/PyCharmProjects/xywy_ask_answer/database/RabbitMQ.py", line 104, in __init__
    self.connection = pika.BlockingConnection(connection_parameter)
  File "/Users/qianlong/Documents/Applications/Anaconda2/anaconda/lib/python2.7/site-packages/pika/adapters/blocking_connection.py", line 339, in __init__
    self._process_io_for_connection_setup()
  File "/Users/qianlong/Documents/Applications/Anaconda2/anaconda/lib/python2.7/site-packages/pika/adapters/blocking_connection.py", line 374, in _process_io_for_connection_setup
    self._open_error_result.is_ready)
  File "/Users/qianlong/Documents/Applications/Anaconda2/anaconda/lib/python2.7/site-packages/pika/adapters/blocking_connection.py", line 395, in _flush_output
    raise exceptions.ConnectionClosed()
ConnectionClosed
 
[2017-08-04 09:39:20]: 
Traceback (most recent call last):
  File "/Users/qianlong/Documents/Workspace/PyCharmProjects/xywy_ask_answer/database/RabbitMQ.py", line 104, in __init__
    self.connection = pika.BlockingConnection(connection_parameter)
  File "/Users/qianlong/Documents/Applications/Anaconda2/anaconda/lib/python2.7/site-packages/pika/adapters/blocking_connection.py", line 339, in __init__
    self._process_io_for_connection_setup()
  File "/Users/qianlong/Documents/Applications/Anaconda2/anaconda/lib/python2.7/site-packages/pika/adapters/blocking_connection.py", line 374, in _process_io_for_connection_setup
    self._open_error_result.is_ready)
  File "/Users/qianlong/Documents/Applications/Anaconda2/anaconda/lib/python2.7/site-packages/pika/adapters/blocking_connection.py", line 395, in _flush_output
    raise exceptions.ConnectionClosed()
ConnectionClosed
 
[2017-08-04 09:39:20]: 
Traceback (most recent call last):
  File "/Users/qianlong/Documents/Workspace/PyCharmProjects/xywy_ask_answer/database/RabbitMQ.py", line 104, in __init__
    self.connection = pika.BlockingConnection(connection_parameter)
  File "/Users/qianlong/Documents/Applications/Anaconda2/anaconda/lib/python2.7/site-packages/pika/adapters/blocking_connection.py", line 339, in __init__
    self._process_io_for_connection_setup()
  File "/Users/qianlong/Documents/Applications/Anaconda2/anaconda/lib/python2.7/site-packages/pika/adapters/blocking_connection.py", line 374, in _process_io_for_connection_setup
    self._open_error_result.is_ready)
  File "/Users/qianlong/Documents/Applications/Anaconda2/anaconda/lib/python2.7/site-packages/pika/adapters/blocking_connection.py", line 395, in _flush_output
    raise exceptions.ConnectionClosed()
ConnectionClosed
 
[2017-08-04 09:39:21]: 
Traceback (most recent call last):
  File "/Users/qianlong/Documents/Workspace/PyCharmProjects/xywy_ask_answer/database/RabbitMQ.py", line 104, in __init__
    self.connection = pika.BlockingConnection(connection_parameter)
  File "/Users/qianlong/Documents/Applications/Anaconda2/anaconda/lib/python2.7/site-packages/pika/adapters/blocking_connection.py", line 339, in __init__
    self._process_io_for_connection_setup()
  File "/Users/qianlong/Documents/Applications/Anaconda2/anaconda/lib/python2.7/site-packages/pika/adapters/blocking_connection.py", line 374, in _process_io_for_connection_setup
    self._open_error_result.is_ready)
  File "/Users/qianlong/Documents/Applications/Anaconda2/anaconda/lib/python2.7/site-packages/pika/adapters/blocking_connection.py", line 395, in _flush_output
    raise exceptions.ConnectionClosed()
ConnectionClosed
 
[2017-08-04 09:39:21]: 
Traceback (most recent call last):
  File "/Users/qianlong/Documents/Workspace/PyCharmProjects/xywy_ask_answer/database/RabbitMQ.py", line 104, in __init__
    self.connection = pika.BlockingConnection(connection_parameter)
  File "/Users/qianlong/Documents/Applications/Anaconda2/anaconda/lib/python2.7/site-packages/pika/adapters/blocking_connection.py", line 339, in __init__
    self._process_io_for_connection_setup()
  File "/Users/qianlong/Documents/Applications/Anaconda2/anaconda/lib/python2.7/site-packages/pika/adapters/blocking_connection.py", line 374, in _process_io_for_connection_setup
    self._open_error_result.is_ready)
  File "/Users/qianlong/Documents/Applications/Anaconda2/anaconda/lib/python2.7/site-packages/pika/adapters/blocking_connection.py", line 395, in _flush_output
    raise exceptions.ConnectionClosed()
ConnectionClosed
 
[2017-08-04 10:07:31]: 
Traceback (most recent call last):
  File "/Users/qianlong/Documents/Workspace/PyCharmProjects/xywy_ask_answer/database/RabbitMQ.py", line 104, in __init__
    self.connection = pika.BlockingConnection(connection_parameter)
  File "/Users/qianlong/Documents/Applications/Anaconda2/anaconda/lib/python2.7/site-packages/pika/adapters/blocking_connection.py", line 339, in __init__
    self._process_io_for_connection_setup()
  File "/Users/qianlong/Documents/Applications/Anaconda2/anaconda/lib/python2.7/site-packages/pika/adapters/blocking_connection.py", line 374, in _process_io_for_connection_setup
    self._open_error_result.is_ready)
  File "/Users/qianlong/Documents/Applications/Anaconda2/anaconda/lib/python2.7/site-packages/pika/adapters/blocking_connection.py", line 395, in _flush_output
    raise exceptions.ConnectionClosed()
ConnectionClosed
 
[2017-08-04 10:07:31]: 
Traceback (most recent call last):
  File "/Users/qianlong/Documents/Workspace/PyCharmProjects/xywy_ask_answer/database/RabbitMQ.py", line 104, in __init__
    self.connection = pika.BlockingConnection(connection_parameter)
  File "/Users/qianlong/Documents/Applications/Anaconda2/anaconda/lib/python2.7/site-packages/pika/adapters/blocking_connection.py", line 339, in __init__
    self._process_io_for_connection_setup()
  File "/Users/qianlong/Documents/Applications/Anaconda2/anaconda/lib/python2.7/site-packages/pika/adapters/blocking_connection.py", line 374, in _process_io_for_connection_setup
    self._open_error_result.is_ready)
  File "/Users/qianlong/Documents/Applications/Anaconda2/anaconda/lib/python2.7/site-packages/pika/adapters/blocking_connection.py", line 395, in _flush_output
    raise exceptions.ConnectionClosed()
ConnectionClosed
 
[2017-08-04 10:07:32]: 
Traceback (most recent call last):
  File "/Users/qianlong/Documents/Workspace/PyCharmProjects/xywy_ask_answer/database/RabbitMQ.py", line 104, in __init__
    self.connection = pika.BlockingConnection(connection_parameter)
  File "/Users/qianlong/Documents/Applications/Anaconda2/anaconda/lib/python2.7/site-packages/pika/adapters/blocking_connection.py", line 339, in __init__
    self._process_io_for_connection_setup()
  File "/Users/qianlong/Documents/Applications/Anaconda2/anaconda/lib/python2.7/site-packages/pika/adapters/blocking_connection.py", line 374, in _process_io_for_connection_setup
    self._open_error_result.is_ready)
  File "/Users/qianlong/Documents/Applications/Anaconda2/anaconda/lib/python2.7/site-packages/pika/adapters/blocking_connection.py", line 395, in _flush_output
    raise exceptions.ConnectionClosed()
ConnectionClosed
 
[2017-08-04 10:07:32]: 
Traceback (most recent call last):
  File "/Users/qianlong/Documents/Workspace/PyCharmProjects/xywy_ask_answer/database/RabbitMQ.py", line 104, in __init__
    self.connection = pika.BlockingConnection(connection_parameter)
  File "/Users/qianlong/Documents/Applications/Anaconda2/anaconda/lib/python2.7/site-packages/pika/adapters/blocking_connection.py", line 339, in __init__
    self._process_io_for_connection_setup()
  File "/Users/qianlong/Documents/Applications/Anaconda2/anaconda/lib/python2.7/site-packages/pika/adapters/blocking_connection.py", line 374, in _process_io_for_connection_setup
    self._open_error_result.is_ready)
  File "/Users/qianlong/Documents/Applications/Anaconda2/anaconda/lib/python2.7/site-packages/pika/adapters/blocking_connection.py", line 395, in _flush_output
    raise exceptions.ConnectionClosed()
ConnectionClosed
 
[2017-08-04 10:07:32]: 
Traceback (most recent call last):
  File "/Users/qianlong/Documents/Workspace/PyCharmProjects/xywy_ask_answer/database/RabbitMQ.py", line 104, in __init__
    self.connection = pika.BlockingConnection(connection_parameter)
  File "/Users/qianlong/Documents/Applications/Anaconda2/anaconda/lib/python2.7/site-packages/pika/adapters/blocking_connection.py", line 339, in __init__
    self._process_io_for_connection_setup()
  File "/Users/qianlong/Documents/Applications/Anaconda2/anaconda/lib/python2.7/site-packages/pika/adapters/blocking_connection.py", line 374, in _process_io_for_connection_setup
    self._open_error_result.is_ready)
  File "/Users/qianlong/Documents/Applications/Anaconda2/anaconda/lib/python2.7/site-packages/pika/adapters/blocking_connection.py", line 395, in _flush_output
    raise exceptions.ConnectionClosed()
ConnectionClosed
 
[2017-08-04 10:07:32]: 
Traceback (most recent call last):
  File "/Users/qianlong/Documents/Workspace/PyCharmProjects/xywy_ask_answer/database/RabbitMQ.py", line 104, in __init__
    self.connection = pika.BlockingConnection(connection_parameter)
  File "/Users/qianlong/Documents/Applications/Anaconda2/anaconda/lib/python2.7/site-packages/pika/adapters/blocking_connection.py", line 339, in __init__
    self._process_io_for_connection_setup()
  File "/Users/qianlong/Documents/Applications/Anaconda2/anaconda/lib/python2.7/site-packages/pika/adapters/blocking_connection.py", line 374, in _process_io_for_connection_setup
    self._open_error_result.is_ready)
  File "/Users/qianlong/Documents/Applications/Anaconda2/anaconda/lib/python2.7/site-packages/pika/adapters/blocking_connection.py", line 395, in _flush_output
    raise exceptions.ConnectionClosed()
ConnectionClosed
 
[2017-08-04 10:07:33]: 
Traceback (most recent call last):
  File "/Users/qianlong/Documents/Workspace/PyCharmProjects/xywy_ask_answer/database/RabbitMQ.py", line 104, in __init__
    self.connection = pika.BlockingConnection(connection_parameter)
  File "/Users/qianlong/Documents/Applications/Anaconda2/anaconda/lib/python2.7/site-packages/pika/adapters/blocking_connection.py", line 339, in __init__
    self._process_io_for_connection_setup()
  File "/Users/qianlong/Documents/Applications/Anaconda2/anaconda/lib/python2.7/site-packages/pika/adapters/blocking_connection.py", line 374, in _process_io_for_connection_setup
    self._open_error_result.is_ready)
  File "/Users/qianlong/Documents/Applications/Anaconda2/anaconda/lib/python2.7/site-packages/pika/adapters/blocking_connection.py", line 395, in _flush_output
    raise exceptions.ConnectionClosed()
ConnectionClosed
 
[2017-08-04 10:07:33]: 
Traceback (most recent call last):
  File "/Users/qianlong/Documents/Workspace/PyCharmProjects/xywy_ask_answer/database/RabbitMQ.py", line 104, in __init__
    self.connection = pika.BlockingConnection(connection_parameter)
  File "/Users/qianlong/Documents/Applications/Anaconda2/anaconda/lib/python2.7/site-packages/pika/adapters/blocking_connection.py", line 339, in __init__
    self._process_io_for_connection_setup()
  File "/Users/qianlong/Documents/Applications/Anaconda2/anaconda/lib/python2.7/site-packages/pika/adapters/blocking_connection.py", line 374, in _process_io_for_connection_setup
    self._open_error_result.is_ready)
  File "/Users/qianlong/Documents/Applications/Anaconda2/anaconda/lib/python2.7/site-packages/pika/adapters/blocking_connection.py", line 395, in _flush_output
    raise exceptions.ConnectionClosed()
ConnectionClosed
 
[2017-08-04 10:07:33]: 
Traceback (most recent call last):
  File "/Users/qianlong/Documents/Workspace/PyCharmProjects/xywy_ask_answer/database/RabbitMQ.py", line 104, in __init__
    self.connection = pika.BlockingConnection(connection_parameter)
  File "/Users/qianlong/Documents/Applications/Anaconda2/anaconda/lib/python2.7/site-packages/pika/adapters/blocking_connection.py", line 339, in __init__
    self._process_io_for_connection_setup()
  File "/Users/qianlong/Documents/Applications/Anaconda2/anaconda/lib/python2.7/site-packages/pika/adapters/blocking_connection.py", line 374, in _process_io_for_connection_setup
    self._open_error_result.is_ready)
  File "/Users/qianlong/Documents/Applications/Anaconda2/anaconda/lib/python2.7/site-packages/pika/adapters/blocking_connection.py", line 395, in _flush_output
    raise exceptions.ConnectionClosed()
ConnectionClosed
 
[2017-08-04 10:07:33]: 
Traceback (most recent call last):
  File "/Users/qianlong/Documents/Workspace/PyCharmProjects/xywy_ask_answer/database/RabbitMQ.py", line 104, in __init__
    self.connection = pika.BlockingConnection(connection_parameter)
  File "/Users/qianlong/Documents/Applications/Anaconda2/anaconda/lib/python2.7/site-packages/pika/adapters/blocking_connection.py", line 339, in __init__
    self._process_io_for_connection_setup()
  File "/Users/qianlong/Documents/Applications/Anaconda2/anaconda/lib/python2.7/site-packages/pika/adapters/blocking_connection.py", line 374, in _process_io_for_connection_setup
    self._open_error_result.is_ready)
  File "/Users/qianlong/Documents/Applications/Anaconda2/anaconda/lib/python2.7/site-packages/pika/adapters/blocking_connection.py", line 395, in _flush_output
    raise exceptions.ConnectionClosed()
ConnectionClosed
 
[2017-08-04 10:07:34]: 
Traceback (most recent call last):
  File "/Users/qianlong/Documents/Workspace/PyCharmProjects/xywy_ask_answer/database/RabbitMQ.py", line 104, in __init__
    self.connection = pika.BlockingConnection(connection_parameter)
  File "/Users/qianlong/Documents/Applications/Anaconda2/anaconda/lib/python2.7/site-packages/pika/adapters/blocking_connection.py", line 339, in __init__
    self._process_io_for_connection_setup()
  File "/Users/qianlong/Documents/Applications/Anaconda2/anaconda/lib/python2.7/site-packages/pika/adapters/blocking_connection.py", line 374, in _process_io_for_connection_setup
    self._open_error_result.is_ready)
  File "/Users/qianlong/Documents/Applications/Anaconda2/anaconda/lib/python2.7/site-packages/pika/adapters/blocking_connection.py", line 395, in _flush_output
    raise exceptions.ConnectionClosed()
ConnectionClosed
 
[2017-08-04 10:07:34]: 
Traceback (most recent call last):
  File "/Users/qianlong/Documents/Workspace/PyCharmProjects/xywy_ask_answer/database/RabbitMQ.py", line 104, in __init__
    self.connection = pika.BlockingConnection(connection_parameter)
  File "/Users/qianlong/Documents/Applications/Anaconda2/anaconda/lib/python2.7/site-packages/pika/adapters/blocking_connection.py", line 339, in __init__
    self._process_io_for_connection_setup()
  File "/Users/qianlong/Documents/Applications/Anaconda2/anaconda/lib/python2.7/site-packages/pika/adapters/blocking_connection.py", line 374, in _process_io_for_connection_setup
    self._open_error_result.is_ready)
  File "/Users/qianlong/Documents/Applications/Anaconda2/anaconda/lib/python2.7/site-packages/pika/adapters/blocking_connection.py", line 395, in _flush_output
    raise exceptions.ConnectionClosed()
ConnectionClosed
 
[2017-08-04 10:07:34]: 
Traceback (most recent call last):
  File "/Users/qianlong/Documents/Workspace/PyCharmProjects/xywy_ask_answer/database/RabbitMQ.py", line 104, in __init__
    self.connection = pika.BlockingConnection(connection_parameter)
  File "/Users/qianlong/Documents/Applications/Anaconda2/anaconda/lib/python2.7/site-packages/pika/adapters/blocking_connection.py", line 339, in __init__
    self._process_io_for_connection_setup()
  File "/Users/qianlong/Documents/Applications/Anaconda2/anaconda/lib/python2.7/site-packages/pika/adapters/blocking_connection.py", line 374, in _process_io_for_connection_setup
    self._open_error_result.is_ready)
  File "/Users/qianlong/Documents/Applications/Anaconda2/anaconda/lib/python2.7/site-packages/pika/adapters/blocking_connection.py", line 395, in _flush_output
    raise exceptions.ConnectionClosed()
ConnectionClosed
 
[2017-08-04 10:07:34]: 
Traceback (most recent call last):
  File "/Users/qianlong/Documents/Workspace/PyCharmProjects/xywy_ask_answer/database/RabbitMQ.py", line 104, in __init__
    self.connection = pika.BlockingConnection(connection_parameter)
  File "/Users/qianlong/Documents/Applications/Anaconda2/anaconda/lib/python2.7/site-packages/pika/adapters/blocking_connection.py", line 339, in __init__
    self._process_io_for_connection_setup()
  File "/Users/qianlong/Documents/Applications/Anaconda2/anaconda/lib/python2.7/site-packages/pika/adapters/blocking_connection.py", line 374, in _process_io_for_connection_setup
    self._open_error_result.is_ready)
  File "/Users/qianlong/Documents/Applications/Anaconda2/anaconda/lib/python2.7/site-packages/pika/adapters/blocking_connection.py", line 395, in _flush_output
    raise exceptions.ConnectionClosed()
ConnectionClosed
 
[2017-08-04 10:07:38]: 
Traceback (most recent call last):
  File "/Users/qianlong/Documents/Workspace/PyCharmProjects/xywy_ask_answer/database/RabbitMQ.py", line 104, in __init__
    self.connection = pika.BlockingConnection(connection_parameter)
  File "/Users/qianlong/Documents/Applications/Anaconda2/anaconda/lib/python2.7/site-packages/pika/adapters/blocking_connection.py", line 339, in __init__
    self._process_io_for_connection_setup()
  File "/Users/qianlong/Documents/Applications/Anaconda2/anaconda/lib/python2.7/site-packages/pika/adapters/blocking_connection.py", line 374, in _process_io_for_connection_setup
    self._open_error_result.is_ready)
  File "/Users/qianlong/Documents/Applications/Anaconda2/anaconda/lib/python2.7/site-packages/pika/adapters/blocking_connection.py", line 395, in _flush_output
    raise exceptions.ConnectionClosed()
ConnectionClosed
 
[2017-08-04 10:07:39]: 
Traceback (most recent call last):
  File "/Users/qianlong/Documents/Workspace/PyCharmProjects/xywy_ask_answer/database/RabbitMQ.py", line 104, in __init__
    self.connection = pika.BlockingConnection(connection_parameter)
  File "/Users/qianlong/Documents/Applications/Anaconda2/anaconda/lib/python2.7/site-packages/pika/adapters/blocking_connection.py", line 339, in __init__
    self._process_io_for_connection_setup()
  File "/Users/qianlong/Documents/Applications/Anaconda2/anaconda/lib/python2.7/site-packages/pika/adapters/blocking_connection.py", line 374, in _process_io_for_connection_setup
    self._open_error_result.is_ready)
  File "/Users/qianlong/Documents/Applications/Anaconda2/anaconda/lib/python2.7/site-packages/pika/adapters/blocking_connection.py", line 395, in _flush_output
    raise exceptions.ConnectionClosed()
ConnectionClosed
 
[2017-08-04 10:07:39]: 
Traceback (most recent call last):
  File "/Users/qianlong/Documents/Workspace/PyCharmProjects/xywy_ask_answer/database/RabbitMQ.py", line 104, in __init__
    self.connection = pika.BlockingConnection(connection_parameter)
  File "/Users/qianlong/Documents/Applications/Anaconda2/anaconda/lib/python2.7/site-packages/pika/adapters/blocking_connection.py", line 339, in __init__
    self._process_io_for_connection_setup()
  File "/Users/qianlong/Documents/Applications/Anaconda2/anaconda/lib/python2.7/site-packages/pika/adapters/blocking_connection.py", line 374, in _process_io_for_connection_setup
    self._open_error_result.is_ready)
  File "/Users/qianlong/Documents/Applications/Anaconda2/anaconda/lib/python2.7/site-packages/pika/adapters/blocking_connection.py", line 395, in _flush_output
    raise exceptions.ConnectionClosed()
ConnectionClosed
 
[2017-08-04 10:07:39]: 
Traceback (most recent call last):
  File "/Users/qianlong/Documents/Workspace/PyCharmProjects/xywy_ask_answer/database/RabbitMQ.py", line 104, in __init__
    self.connection = pika.BlockingConnection(connection_parameter)
  File "/Users/qianlong/Documents/Applications/Anaconda2/anaconda/lib/python2.7/site-packages/pika/adapters/blocking_connection.py", line 339, in __init__
    self._process_io_for_connection_setup()
  File "/Users/qianlong/Documents/Applications/Anaconda2/anaconda/lib/python2.7/site-packages/pika/adapters/blocking_connection.py", line 374, in _process_io_for_connection_setup
    self._open_error_result.is_ready)
  File "/Users/qianlong/Documents/Applications/Anaconda2/anaconda/lib/python2.7/site-packages/pika/adapters/blocking_connection.py", line 395, in _flush_output
    raise exceptions.ConnectionClosed()
ConnectionClosed
 
[2017-08-04 10:07:40]: 
Traceback (most recent call last):
  File "/Users/qianlong/Documents/Workspace/PyCharmProjects/xywy_ask_answer/database/RabbitMQ.py", line 104, in __init__
    self.connection = pika.BlockingConnection(connection_parameter)
  File "/Users/qianlong/Documents/Applications/Anaconda2/anaconda/lib/python2.7/site-packages/pika/adapters/blocking_connection.py", line 339, in __init__
    self._process_io_for_connection_setup()
  File "/Users/qianlong/Documents/Applications/Anaconda2/anaconda/lib/python2.7/site-packages/pika/adapters/blocking_connection.py", line 374, in _process_io_for_connection_setup
    self._open_error_result.is_ready)
  File "/Users/qianlong/Documents/Applications/Anaconda2/anaconda/lib/python2.7/site-packages/pika/adapters/blocking_connection.py", line 395, in _flush_output
    raise exceptions.ConnectionClosed()
ConnectionClosed
 
[2017-08-04 10:07:40]: 
Traceback (most recent call last):
  File "/Users/qianlong/Documents/Workspace/PyCharmProjects/xywy_ask_answer/database/RabbitMQ.py", line 104, in __init__
    self.connection = pika.BlockingConnection(connection_parameter)
  File "/Users/qianlong/Documents/Applications/Anaconda2/anaconda/lib/python2.7/site-packages/pika/adapters/blocking_connection.py", line 339, in __init__
    self._process_io_for_connection_setup()
  File "/Users/qianlong/Documents/Applications/Anaconda2/anaconda/lib/python2.7/site-packages/pika/adapters/blocking_connection.py", line 374, in _process_io_for_connection_setup
    self._open_error_result.is_ready)
  File "/Users/qianlong/Documents/Applications/Anaconda2/anaconda/lib/python2.7/site-packages/pika/adapters/blocking_connection.py", line 395, in _flush_output
    raise exceptions.ConnectionClosed()
ConnectionClosed
 
[2017-08-04 10:07:40]: 
Traceback (most recent call last):
  File "/Users/qianlong/Documents/Workspace/PyCharmProjects/xywy_ask_answer/database/RabbitMQ.py", line 104, in __init__
    self.connection = pika.BlockingConnection(connection_parameter)
  File "/Users/qianlong/Documents/Applications/Anaconda2/anaconda/lib/python2.7/site-packages/pika/adapters/blocking_connection.py", line 339, in __init__
    self._process_io_for_connection_setup()
  File "/Users/qianlong/Documents/Applications/Anaconda2/anaconda/lib/python2.7/site-packages/pika/adapters/blocking_connection.py", line 374, in _process_io_for_connection_setup
    self._open_error_result.is_ready)
  File "/Users/qianlong/Documents/Applications/Anaconda2/anaconda/lib/python2.7/site-packages/pika/adapters/blocking_connection.py", line 395, in _flush_output
    raise exceptions.ConnectionClosed()
ConnectionClosed
 
[2017-08-04 10:07:40]: 
Traceback (most recent call last):
  File "/Users/qianlong/Documents/Workspace/PyCharmProjects/xywy_ask_answer/database/RabbitMQ.py", line 104, in __init__
    self.connection = pika.BlockingConnection(connection_parameter)
  File "/Users/qianlong/Documents/Applications/Anaconda2/anaconda/lib/python2.7/site-packages/pika/adapters/blocking_connection.py", line 339, in __init__
    self._process_io_for_connection_setup()
  File "/Users/qianlong/Documents/Applications/Anaconda2/anaconda/lib/python2.7/site-packages/pika/adapters/blocking_connection.py", line 374, in _process_io_for_connection_setup
    self._open_error_result.is_ready)
  File "/Users/qianlong/Documents/Applications/Anaconda2/anaconda/lib/python2.7/site-packages/pika/adapters/blocking_connection.py", line 395, in _flush_output
    raise exceptions.ConnectionClosed()
ConnectionClosed
 
[2017-08-04 10:07:41]: 
Traceback (most recent call last):
  File "/Users/qianlong/Documents/Workspace/PyCharmProjects/xywy_ask_answer/database/RabbitMQ.py", line 104, in __init__
    self.connection = pika.BlockingConnection(connection_parameter)
  File "/Users/qianlong/Documents/Applications/Anaconda2/anaconda/lib/python2.7/site-packages/pika/adapters/blocking_connection.py", line 339, in __init__
    self._process_io_for_connection_setup()
  File "/Users/qianlong/Documents/Applications/Anaconda2/anaconda/lib/python2.7/site-packages/pika/adapters/blocking_connection.py", line 374, in _process_io_for_connection_setup
    self._open_error_result.is_ready)
  File "/Users/qianlong/Documents/Applications/Anaconda2/anaconda/lib/python2.7/site-packages/pika/adapters/blocking_connection.py", line 395, in _flush_output
    raise exceptions.ConnectionClosed()
ConnectionClosed
 
[2017-08-04 10:07:41]: 
Traceback (most recent call last):
  File "/Users/qianlong/Documents/Workspace/PyCharmProjects/xywy_ask_answer/database/RabbitMQ.py", line 104, in __init__
    self.connection = pika.BlockingConnection(connection_parameter)
  File "/Users/qianlong/Documents/Applications/Anaconda2/anaconda/lib/python2.7/site-packages/pika/adapters/blocking_connection.py", line 339, in __init__
    self._process_io_for_connection_setup()
  File "/Users/qianlong/Documents/Applications/Anaconda2/anaconda/lib/python2.7/site-packages/pika/adapters/blocking_connection.py", line 374, in _process_io_for_connection_setup
    self._open_error_result.is_ready)
  File "/Users/qianlong/Documents/Applications/Anaconda2/anaconda/lib/python2.7/site-packages/pika/adapters/blocking_connection.py", line 395, in _flush_output
    raise exceptions.ConnectionClosed()
ConnectionClosed
 
[2017-08-04 10:07:41]: 
Traceback (most recent call last):
  File "/Users/qianlong/Documents/Workspace/PyCharmProjects/xywy_ask_answer/database/RabbitMQ.py", line 104, in __init__
    self.connection = pika.BlockingConnection(connection_parameter)
  File "/Users/qianlong/Documents/Applications/Anaconda2/anaconda/lib/python2.7/site-packages/pika/adapters/blocking_connection.py", line 339, in __init__
    self._process_io_for_connection_setup()
  File "/Users/qianlong/Documents/Applications/Anaconda2/anaconda/lib/python2.7/site-packages/pika/adapters/blocking_connection.py", line 374, in _process_io_for_connection_setup
    self._open_error_result.is_ready)
  File "/Users/qianlong/Documents/Applications/Anaconda2/anaconda/lib/python2.7/site-packages/pika/adapters/blocking_connection.py", line 395, in _flush_output
    raise exceptions.ConnectionClosed()
ConnectionClosed
 
[2017-08-04 10:07:41]: 
Traceback (most recent call last):
  File "/Users/qianlong/Documents/Workspace/PyCharmProjects/xywy_ask_answer/database/RabbitMQ.py", line 104, in __init__
    self.connection = pika.BlockingConnection(connection_parameter)
  File "/Users/qianlong/Documents/Applications/Anaconda2/anaconda/lib/python2.7/site-packages/pika/adapters/blocking_connection.py", line 339, in __init__
    self._process_io_for_connection_setup()
  File "/Users/qianlong/Documents/Applications/Anaconda2/anaconda/lib/python2.7/site-packages/pika/adapters/blocking_connection.py", line 374, in _process_io_for_connection_setup
    self._open_error_result.is_ready)
  File "/Users/qianlong/Documents/Applications/Anaconda2/anaconda/lib/python2.7/site-packages/pika/adapters/blocking_connection.py", line 395, in _flush_output
    raise exceptions.ConnectionClosed()
ConnectionClosed
 
[2017-08-04 10:07:42]: 
Traceback (most recent call last):
  File "/Users/qianlong/Documents/Workspace/PyCharmProjects/xywy_ask_answer/database/RabbitMQ.py", line 104, in __init__
    self.connection = pika.BlockingConnection(connection_parameter)
  File "/Users/qianlong/Documents/Applications/Anaconda2/anaconda/lib/python2.7/site-packages/pika/adapters/blocking_connection.py", line 339, in __init__
    self._process_io_for_connection_setup()
  File "/Users/qianlong/Documents/Applications/Anaconda2/anaconda/lib/python2.7/site-packages/pika/adapters/blocking_connection.py", line 374, in _process_io_for_connection_setup
    self._open_error_result.is_ready)
  File "/Users/qianlong/Documents/Applications/Anaconda2/anaconda/lib/python2.7/site-packages/pika/adapters/blocking_connection.py", line 395, in _flush_output
    raise exceptions.ConnectionClosed()
ConnectionClosed
 
[2017-08-04 10:07:42]: 
Traceback (most recent call last):
  File "/Users/qianlong/Documents/Workspace/PyCharmProjects/xywy_ask_answer/database/RabbitMQ.py", line 104, in __init__
    self.connection = pika.BlockingConnection(connection_parameter)
  File "/Users/qianlong/Documents/Applications/Anaconda2/anaconda/lib/python2.7/site-packages/pika/adapters/blocking_connection.py", line 339, in __init__
    self._process_io_for_connection_setup()
  File "/Users/qianlong/Documents/Applications/Anaconda2/anaconda/lib/python2.7/site-packages/pika/adapters/blocking_connection.py", line 374, in _process_io_for_connection_setup
    self._open_error_result.is_ready)
  File "/Users/qianlong/Documents/Applications/Anaconda2/anaconda/lib/python2.7/site-packages/pika/adapters/blocking_connection.py", line 395, in _flush_output
    raise exceptions.ConnectionClosed()
ConnectionClosed
 
[2017-08-04 10:07:50]: 
Traceback (most recent call last):
  File "/Users/qianlong/Documents/Workspace/PyCharmProjects/xywy_ask_answer/database/RabbitMQ.py", line 104, in __init__
    self.connection = pika.BlockingConnection(connection_parameter)
  File "/Users/qianlong/Documents/Applications/Anaconda2/anaconda/lib/python2.7/site-packages/pika/adapters/blocking_connection.py", line 339, in __init__
    self._process_io_for_connection_setup()
  File "/Users/qianlong/Documents/Applications/Anaconda2/anaconda/lib/python2.7/site-packages/pika/adapters/blocking_connection.py", line 374, in _process_io_for_connection_setup
    self._open_error_result.is_ready)
  File "/Users/qianlong/Documents/Applications/Anaconda2/anaconda/lib/python2.7/site-packages/pika/adapters/blocking_connection.py", line 395, in _flush_output
    raise exceptions.ConnectionClosed()
ConnectionClosed
 
[2017-08-04 10:07:50]: 
Traceback (most recent call last):
  File "/Users/qianlong/Documents/Workspace/PyCharmProjects/xywy_ask_answer/database/RabbitMQ.py", line 104, in __init__
    self.connection = pika.BlockingConnection(connection_parameter)
  File "/Users/qianlong/Documents/Applications/Anaconda2/anaconda/lib/python2.7/site-packages/pika/adapters/blocking_connection.py", line 339, in __init__
    self._process_io_for_connection_setup()
  File "/Users/qianlong/Documents/Applications/Anaconda2/anaconda/lib/python2.7/site-packages/pika/adapters/blocking_connection.py", line 374, in _process_io_for_connection_setup
    self._open_error_result.is_ready)
  File "/Users/qianlong/Documents/Applications/Anaconda2/anaconda/lib/python2.7/site-packages/pika/adapters/blocking_connection.py", line 395, in _flush_output
    raise exceptions.ConnectionClosed()
ConnectionClosed
 
[2017-08-04 10:07:51]: 
Traceback (most recent call last):
  File "/Users/qianlong/Documents/Workspace/PyCharmProjects/xywy_ask_answer/database/RabbitMQ.py", line 104, in __init__
    self.connection = pika.BlockingConnection(connection_parameter)
  File "/Users/qianlong/Documents/Applications/Anaconda2/anaconda/lib/python2.7/site-packages/pika/adapters/blocking_connection.py", line 339, in __init__
    self._process_io_for_connection_setup()
  File "/Users/qianlong/Documents/Applications/Anaconda2/anaconda/lib/python2.7/site-packages/pika/adapters/blocking_connection.py", line 374, in _process_io_for_connection_setup
    self._open_error_result.is_ready)
  File "/Users/qianlong/Documents/Applications/Anaconda2/anaconda/lib/python2.7/site-packages/pika/adapters/blocking_connection.py", line 395, in _flush_output
    raise exceptions.ConnectionClosed()
ConnectionClosed
 
[2017-08-04 10:07:51]: 
Traceback (most recent call last):
  File "/Users/qianlong/Documents/Workspace/PyCharmProjects/xywy_ask_answer/database/RabbitMQ.py", line 104, in __init__
    self.connection = pika.BlockingConnection(connection_parameter)
  File "/Users/qianlong/Documents/Applications/Anaconda2/anaconda/lib/python2.7/site-packages/pika/adapters/blocking_connection.py", line 339, in __init__
    self._process_io_for_connection_setup()
  File "/Users/qianlong/Documents/Applications/Anaconda2/anaconda/lib/python2.7/site-packages/pika/adapters/blocking_connection.py", line 374, in _process_io_for_connection_setup
    self._open_error_result.is_ready)
  File "/Users/qianlong/Documents/Applications/Anaconda2/anaconda/lib/python2.7/site-packages/pika/adapters/blocking_connection.py", line 395, in _flush_output
    raise exceptions.ConnectionClosed()
ConnectionClosed
 
[2017-08-04 10:07:51]: 
Traceback (most recent call last):
  File "/Users/qianlong/Documents/Workspace/PyCharmProjects/xywy_ask_answer/database/RabbitMQ.py", line 104, in __init__
    self.connection = pika.BlockingConnection(connection_parameter)
  File "/Users/qianlong/Documents/Applications/Anaconda2/anaconda/lib/python2.7/site-packages/pika/adapters/blocking_connection.py", line 339, in __init__
    self._process_io_for_connection_setup()
  File "/Users/qianlong/Documents/Applications/Anaconda2/anaconda/lib/python2.7/site-packages/pika/adapters/blocking_connection.py", line 374, in _process_io_for_connection_setup
    self._open_error_result.is_ready)
  File "/Users/qianlong/Documents/Applications/Anaconda2/anaconda/lib/python2.7/site-packages/pika/adapters/blocking_connection.py", line 395, in _flush_output
    raise exceptions.ConnectionClosed()
ConnectionClosed
 
[2017-08-04 10:07:51]: 
Traceback (most recent call last):
  File "/Users/qianlong/Documents/Workspace/PyCharmProjects/xywy_ask_answer/database/RabbitMQ.py", line 104, in __init__
    self.connection = pika.BlockingConnection(connection_parameter)
  File "/Users/qianlong/Documents/Applications/Anaconda2/anaconda/lib/python2.7/site-packages/pika/adapters/blocking_connection.py", line 339, in __init__
    self._process_io_for_connection_setup()
  File "/Users/qianlong/Documents/Applications/Anaconda2/anaconda/lib/python2.7/site-packages/pika/adapters/blocking_connection.py", line 374, in _process_io_for_connection_setup
    self._open_error_result.is_ready)
  File "/Users/qianlong/Documents/Applications/Anaconda2/anaconda/lib/python2.7/site-packages/pika/adapters/blocking_connection.py", line 395, in _flush_output
    raise exceptions.ConnectionClosed()
ConnectionClosed
 
[2017-08-04 10:07:52]: 
Traceback (most recent call last):
  File "/Users/qianlong/Documents/Workspace/PyCharmProjects/xywy_ask_answer/database/RabbitMQ.py", line 104, in __init__
    self.connection = pika.BlockingConnection(connection_parameter)
  File "/Users/qianlong/Documents/Applications/Anaconda2/anaconda/lib/python2.7/site-packages/pika/adapters/blocking_connection.py", line 339, in __init__
    self._process_io_for_connection_setup()
  File "/Users/qianlong/Documents/Applications/Anaconda2/anaconda/lib/python2.7/site-packages/pika/adapters/blocking_connection.py", line 374, in _process_io_for_connection_setup
    self._open_error_result.is_ready)
  File "/Users/qianlong/Documents/Applications/Anaconda2/anaconda/lib/python2.7/site-packages/pika/adapters/blocking_connection.py", line 395, in _flush_output
    raise exceptions.ConnectionClosed()
ConnectionClosed
 
[2017-08-04 10:07:52]: 
Traceback (most recent call last):
  File "/Users/qianlong/Documents/Workspace/PyCharmProjects/xywy_ask_answer/database/RabbitMQ.py", line 104, in __init__
    self.connection = pika.BlockingConnection(connection_parameter)
  File "/Users/qianlong/Documents/Applications/Anaconda2/anaconda/lib/python2.7/site-packages/pika/adapters/blocking_connection.py", line 339, in __init__
    self._process_io_for_connection_setup()
  File "/Users/qianlong/Documents/Applications/Anaconda2/anaconda/lib/python2.7/site-packages/pika/adapters/blocking_connection.py", line 374, in _process_io_for_connection_setup
    self._open_error_result.is_ready)
  File "/Users/qianlong/Documents/Applications/Anaconda2/anaconda/lib/python2.7/site-packages/pika/adapters/blocking_connection.py", line 395, in _flush_output
    raise exceptions.ConnectionClosed()
ConnectionClosed
 
[2017-08-04 10:07:54]: 
Traceback (most recent call last):
  File "/Users/qianlong/Documents/Workspace/PyCharmProjects/xywy_ask_answer/database/RabbitMQ.py", line 104, in __init__
    self.connection = pika.BlockingConnection(connection_parameter)
  File "/Users/qianlong/Documents/Applications/Anaconda2/anaconda/lib/python2.7/site-packages/pika/adapters/blocking_connection.py", line 339, in __init__
    self._process_io_for_connection_setup()
  File "/Users/qianlong/Documents/Applications/Anaconda2/anaconda/lib/python2.7/site-packages/pika/adapters/blocking_connection.py", line 374, in _process_io_for_connection_setup
    self._open_error_result.is_ready)
  File "/Users/qianlong/Documents/Applications/Anaconda2/anaconda/lib/python2.7/site-packages/pika/adapters/blocking_connection.py", line 395, in _flush_output
    raise exceptions.ConnectionClosed()
ConnectionClosed
 
[2017-08-04 10:07:54]: 
Traceback (most recent call last):
  File "/Users/qianlong/Documents/Workspace/PyCharmProjects/xywy_ask_answer/database/RabbitMQ.py", line 104, in __init__
    self.connection = pika.BlockingConnection(connection_parameter)
  File "/Users/qianlong/Documents/Applications/Anaconda2/anaconda/lib/python2.7/site-packages/pika/adapters/blocking_connection.py", line 339, in __init__
    self._process_io_for_connection_setup()
  File "/Users/qianlong/Documents/Applications/Anaconda2/anaconda/lib/python2.7/site-packages/pika/adapters/blocking_connection.py", line 374, in _process_io_for_connection_setup
    self._open_error_result.is_ready)
  File "/Users/qianlong/Documents/Applications/Anaconda2/anaconda/lib/python2.7/site-packages/pika/adapters/blocking_connection.py", line 395, in _flush_output
    raise exceptions.ConnectionClosed()
ConnectionClosed
 
[2017-08-04 10:07:54]: 
Traceback (most recent call last):
  File "/Users/qianlong/Documents/Workspace/PyCharmProjects/xywy_ask_answer/database/RabbitMQ.py", line 104, in __init__
    self.connection = pika.BlockingConnection(connection_parameter)
  File "/Users/qianlong/Documents/Applications/Anaconda2/anaconda/lib/python2.7/site-packages/pika/adapters/blocking_connection.py", line 339, in __init__
    self._process_io_for_connection_setup()
  File "/Users/qianlong/Documents/Applications/Anaconda2/anaconda/lib/python2.7/site-packages/pika/adapters/blocking_connection.py", line 374, in _process_io_for_connection_setup
    self._open_error_result.is_ready)
  File "/Users/qianlong/Documents/Applications/Anaconda2/anaconda/lib/python2.7/site-packages/pika/adapters/blocking_connection.py", line 395, in _flush_output
    raise exceptions.ConnectionClosed()
ConnectionClosed
 
[2017-08-04 10:07:55]: 
Traceback (most recent call last):
  File "/Users/qianlong/Documents/Workspace/PyCharmProjects/xywy_ask_answer/database/RabbitMQ.py", line 104, in __init__
    self.connection = pika.BlockingConnection(connection_parameter)
  File "/Users/qianlong/Documents/Applications/Anaconda2/anaconda/lib/python2.7/site-packages/pika/adapters/blocking_connection.py", line 339, in __init__
    self._process_io_for_connection_setup()
  File "/Users/qianlong/Documents/Applications/Anaconda2/anaconda/lib/python2.7/site-packages/pika/adapters/blocking_connection.py", line 374, in _process_io_for_connection_setup
    self._open_error_result.is_ready)
  File "/Users/qianlong/Documents/Applications/Anaconda2/anaconda/lib/python2.7/site-packages/pika/adapters/blocking_connection.py", line 395, in _flush_output
    raise exceptions.ConnectionClosed()
ConnectionClosed
 
[2017-08-04 10:07:55]: 
Traceback (most recent call last):
  File "/Users/qianlong/Documents/Workspace/PyCharmProjects/xywy_ask_answer/database/RabbitMQ.py", line 104, in __init__
    self.connection = pika.BlockingConnection(connection_parameter)
  File "/Users/qianlong/Documents/Applications/Anaconda2/anaconda/lib/python2.7/site-packages/pika/adapters/blocking_connection.py", line 339, in __init__
    self._process_io_for_connection_setup()
  File "/Users/qianlong/Documents/Applications/Anaconda2/anaconda/lib/python2.7/site-packages/pika/adapters/blocking_connection.py", line 374, in _process_io_for_connection_setup
    self._open_error_result.is_ready)
  File "/Users/qianlong/Documents/Applications/Anaconda2/anaconda/lib/python2.7/site-packages/pika/adapters/blocking_connection.py", line 395, in _flush_output
    raise exceptions.ConnectionClosed()
ConnectionClosed
 
[2017-08-04 10:07:55]: 
Traceback (most recent call last):
  File "/Users/qianlong/Documents/Workspace/PyCharmProjects/xywy_ask_answer/database/RabbitMQ.py", line 104, in __init__
    self.connection = pika.BlockingConnection(connection_parameter)
  File "/Users/qianlong/Documents/Applications/Anaconda2/anaconda/lib/python2.7/site-packages/pika/adapters/blocking_connection.py", line 339, in __init__
    self._process_io_for_connection_setup()
  File "/Users/qianlong/Documents/Applications/Anaconda2/anaconda/lib/python2.7/site-packages/pika/adapters/blocking_connection.py", line 374, in _process_io_for_connection_setup
    self._open_error_result.is_ready)
  File "/Users/qianlong/Documents/Applications/Anaconda2/anaconda/lib/python2.7/site-packages/pika/adapters/blocking_connection.py", line 395, in _flush_output
    raise exceptions.ConnectionClosed()
ConnectionClosed
 
[2017-08-04 10:07:55]: 
Traceback (most recent call last):
  File "/Users/qianlong/Documents/Workspace/PyCharmProjects/xywy_ask_answer/database/RabbitMQ.py", line 104, in __init__
    self.connection = pika.BlockingConnection(connection_parameter)
  File "/Users/qianlong/Documents/Applications/Anaconda2/anaconda/lib/python2.7/site-packages/pika/adapters/blocking_connection.py", line 339, in __init__
    self._process_io_for_connection_setup()
  File "/Users/qianlong/Documents/Applications/Anaconda2/anaconda/lib/python2.7/site-packages/pika/adapters/blocking_connection.py", line 374, in _process_io_for_connection_setup
    self._open_error_result.is_ready)
  File "/Users/qianlong/Documents/Applications/Anaconda2/anaconda/lib/python2.7/site-packages/pika/adapters/blocking_connection.py", line 395, in _flush_output
    raise exceptions.ConnectionClosed()
ConnectionClosed
 
[2017-08-04 10:07:56]: 
Traceback (most recent call last):
  File "/Users/qianlong/Documents/Workspace/PyCharmProjects/xywy_ask_answer/database/RabbitMQ.py", line 104, in __init__
    self.connection = pika.BlockingConnection(connection_parameter)
  File "/Users/qianlong/Documents/Applications/Anaconda2/anaconda/lib/python2.7/site-packages/pika/adapters/blocking_connection.py", line 339, in __init__
    self._process_io_for_connection_setup()
  File "/Users/qianlong/Documents/Applications/Anaconda2/anaconda/lib/python2.7/site-packages/pika/adapters/blocking_connection.py", line 374, in _process_io_for_connection_setup
    self._open_error_result.is_ready)
  File "/Users/qianlong/Documents/Applications/Anaconda2/anaconda/lib/python2.7/site-packages/pika/adapters/blocking_connection.py", line 395, in _flush_output
    raise exceptions.ConnectionClosed()
ConnectionClosed
 
[2017-08-04 10:07:56]: 
Traceback (most recent call last):
  File "/Users/qianlong/Documents/Workspace/PyCharmProjects/xywy_ask_answer/database/RabbitMQ.py", line 104, in __init__
    self.connection = pika.BlockingConnection(connection_parameter)
  File "/Users/qianlong/Documents/Applications/Anaconda2/anaconda/lib/python2.7/site-packages/pika/adapters/blocking_connection.py", line 339, in __init__
    self._process_io_for_connection_setup()
  File "/Users/qianlong/Documents/Applications/Anaconda2/anaconda/lib/python2.7/site-packages/pika/adapters/blocking_connection.py", line 374, in _process_io_for_connection_setup
    self._open_error_result.is_ready)
  File "/Users/qianlong/Documents/Applications/Anaconda2/anaconda/lib/python2.7/site-packages/pika/adapters/blocking_connection.py", line 395, in _flush_output
    raise exceptions.ConnectionClosed()
ConnectionClosed
 
[2017-08-04 10:07:56]: 
Traceback (most recent call last):
  File "/Users/qianlong/Documents/Workspace/PyCharmProjects/xywy_ask_answer/database/RabbitMQ.py", line 104, in __init__
    self.connection = pika.BlockingConnection(connection_parameter)
  File "/Users/qianlong/Documents/Applications/Anaconda2/anaconda/lib/python2.7/site-packages/pika/adapters/blocking_connection.py", line 339, in __init__
    self._process_io_for_connection_setup()
  File "/Users/qianlong/Documents/Applications/Anaconda2/anaconda/lib/python2.7/site-packages/pika/adapters/blocking_connection.py", line 374, in _process_io_for_connection_setup
    self._open_error_result.is_ready)
  File "/Users/qianlong/Documents/Applications/Anaconda2/anaconda/lib/python2.7/site-packages/pika/adapters/blocking_connection.py", line 395, in _flush_output
    raise exceptions.ConnectionClosed()
ConnectionClosed
 
[2017-08-04 10:20:11]: 
Traceback (most recent call last):
  File "/Users/qianlong/Documents/Workspace/PyCharmProjects/xywy_ask_answer/database/RabbitMQ.py", line 104, in __init__
    self.connection = pika.BlockingConnection(connection_parameter)
  File "/Users/qianlong/Documents/Applications/Anaconda2/anaconda/lib/python2.7/site-packages/pika/adapters/blocking_connection.py", line 339, in __init__
    self._process_io_for_connection_setup()
  File "/Users/qianlong/Documents/Applications/Anaconda2/anaconda/lib/python2.7/site-packages/pika/adapters/blocking_connection.py", line 374, in _process_io_for_connection_setup
    self._open_error_result.is_ready)
  File "/Users/qianlong/Documents/Applications/Anaconda2/anaconda/lib/python2.7/site-packages/pika/adapters/blocking_connection.py", line 410, in _flush_output
    self._impl.ioloop.poll()
  File "/Users/qianlong/Documents/Applications/Anaconda2/anaconda/lib/python2.7/site-packages/pika/adapters/select_connection.py", line 528, in poll
    self._process_fd_events(fd_event_map, write_only)
  File "/Users/qianlong/Documents/Applications/Anaconda2/anaconda/lib/python2.7/site-packages/pika/adapters/select_connection.py", line 443, in _process_fd_events
    handler(fileno, events, write_only=write_only)
  File "/Users/qianlong/Documents/Applications/Anaconda2/anaconda/lib/python2.7/site-packages/pika/adapters/base_connection.py", line 364, in _handle_events
    self._handle_read()
  File "/Users/qianlong/Documents/Applications/Anaconda2/anaconda/lib/python2.7/site-packages/pika/adapters/base_connection.py", line 407, in _handle_read
    return self._handle_error(error)
  File "/Users/qianlong/Documents/Applications/Anaconda2/anaconda/lib/python2.7/site-packages/pika/adapters/base_connection.py", line 338, in _handle_error
    self._handle_disconnect()
  File "/Users/qianlong/Documents/Applications/Anaconda2/anaconda/lib/python2.7/site-packages/pika/adapters/base_connection.py", line 288, in _handle_disconnect
    self._adapter_disconnect()
  File "/Users/qianlong/Documents/Applications/Anaconda2/anaconda/lib/python2.7/site-packages/pika/adapters/select_connection.py", line 95, in _adapter_disconnect
    super(SelectConnection, self)._adapter_disconnect()
  File "/Users/qianlong/Documents/Applications/Anaconda2/anaconda/lib/python2.7/site-packages/pika/adapters/base_connection.py", line 154, in _adapter_disconnect
    self._check_state_on_disconnect()
  File "/Users/qianlong/Documents/Applications/Anaconda2/anaconda/lib/python2.7/site-packages/pika/adapters/base_connection.py", line 173, in _check_state_on_disconnect
    raise exceptions.ProbableAuthenticationError
ProbableAuthenticationError
 
[2017-08-04 10:20:15]: 
Traceback (most recent call last):
  File "/Users/qianlong/Documents/Workspace/PyCharmProjects/xywy_ask_answer/database/RabbitMQ.py", line 104, in __init__
    self.connection = pika.BlockingConnection(connection_parameter)
  File "/Users/qianlong/Documents/Applications/Anaconda2/anaconda/lib/python2.7/site-packages/pika/adapters/blocking_connection.py", line 339, in __init__
    self._process_io_for_connection_setup()
  File "/Users/qianlong/Documents/Applications/Anaconda2/anaconda/lib/python2.7/site-packages/pika/adapters/blocking_connection.py", line 374, in _process_io_for_connection_setup
    self._open_error_result.is_ready)
  File "/Users/qianlong/Documents/Applications/Anaconda2/anaconda/lib/python2.7/site-packages/pika/adapters/blocking_connection.py", line 410, in _flush_output
    self._impl.ioloop.poll()
  File "/Users/qianlong/Documents/Applications/Anaconda2/anaconda/lib/python2.7/site-packages/pika/adapters/select_connection.py", line 528, in poll
    self._process_fd_events(fd_event_map, write_only)
  File "/Users/qianlong/Documents/Applications/Anaconda2/anaconda/lib/python2.7/site-packages/pika/adapters/select_connection.py", line 443, in _process_fd_events
    handler(fileno, events, write_only=write_only)
  File "/Users/qianlong/Documents/Applications/Anaconda2/anaconda/lib/python2.7/site-packages/pika/adapters/base_connection.py", line 364, in _handle_events
    self._handle_read()
  File "/Users/qianlong/Documents/Applications/Anaconda2/anaconda/lib/python2.7/site-packages/pika/adapters/base_connection.py", line 407, in _handle_read
    return self._handle_error(error)
  File "/Users/qianlong/Documents/Applications/Anaconda2/anaconda/lib/python2.7/site-packages/pika/adapters/base_connection.py", line 338, in _handle_error
    self._handle_disconnect()
  File "/Users/qianlong/Documents/Applications/Anaconda2/anaconda/lib/python2.7/site-packages/pika/adapters/base_connection.py", line 288, in _handle_disconnect
    self._adapter_disconnect()
  File "/Users/qianlong/Documents/Applications/Anaconda2/anaconda/lib/python2.7/site-packages/pika/adapters/select_connection.py", line 95, in _adapter_disconnect
    super(SelectConnection, self)._adapter_disconnect()
  File "/Users/qianlong/Documents/Applications/Anaconda2/anaconda/lib/python2.7/site-packages/pika/adapters/base_connection.py", line 154, in _adapter_disconnect
    self._check_state_on_disconnect()
  File "/Users/qianlong/Documents/Applications/Anaconda2/anaconda/lib/python2.7/site-packages/pika/adapters/base_connection.py", line 173, in _check_state_on_disconnect
    raise exceptions.ProbableAuthenticationError
ProbableAuthenticationError
 
[2017-08-04 12:24:13]: 

[2017-08-04 12:24:14]: 

[2017-08-04 12:24:14]: 

[2017-08-04 12:24:14]: 

[2017-08-04 12:24:14]: 

[2017-08-04 12:24:14]: 

[2017-08-04 12:24:14]: 

[2017-08-04 12:24:15]: 

[2017-08-04 12:24:16]: 

[2017-08-04 12:24:16]: 

[2017-08-04 12:24:16]: 

[2017-08-04 12:24:16]: 

[2017-08-04 12:24:16]: 

[2017-08-04 12:24:17]: 

[2017-08-04 12:24:17]: 

[2017-08-04 12:24:17]: 

[2017-08-04 12:24:17]: 

[2017-08-04 12:24:17]: 

[2017-08-04 12:24:17]: 

[2017-08-04 12:24:18]: 

[2017-08-04 12:24:18]: 

[2017-08-04 12:24:18]: 
Traceback (most recent call last):
  File "/Users/qianlong/Documents/Workspace/PyCharmProjects/xywy_ask_answer/spiders/ProcessDayUrlSpider.py", line 35, in parse
    page_numer_content = self.selector.xpath('//div[@class="club_page"]/div/text()')[-1]
AttributeError: 'NoneType' object has no attribute 'xpath'
 'NoneType' object has no attribute 'xpath'
[2017-08-04 12:26:01]: 

[2017-08-04 12:26:01]: 

[2017-08-04 12:26:01]: 

[2017-08-04 12:26:01]: 

[2017-08-04 12:26:02]: 

[2017-08-04 12:26:02]: 

[2017-08-04 12:26:02]: 

[2017-08-04 12:26:02]: 

[2017-08-04 12:26:02]: 

[2017-08-04 12:26:03]: 

[2017-08-04 12:26:03]: 

[2017-08-04 12:26:03]: 

[2017-08-04 12:26:03]: 

[2017-08-04 12:26:03]: 

[2017-08-04 12:26:04]: 

[2017-08-04 12:26:04]: 

[2017-08-04 12:26:04]: 

[2017-08-04 12:26:04]: 

[2017-08-04 12:26:04]: 

[2017-08-04 12:26:04]: 

[2017-08-04 12:26:05]: 

[2017-08-04 12:26:05]: 
Traceback (most recent call last):
  File "/Users/qianlong/Documents/Workspace/PyCharmProjects/xywy_ask_answer/spiders/ProcessDayUrlSpider.py", line 35, in parse
    page_numer_content = self.selector.xpath('//div[@class="club_page"]/div/text()')[-1]
AttributeError: 'NoneType' object has no attribute 'xpath'
 'NoneType' object has no attribute 'xpath'
[2017-08-04 12:30:04]: 

[2017-08-04 12:30:04]: 

[2017-08-04 12:30:05]: 

[2017-08-04 12:30:05]: 

[2017-08-04 12:30:05]: 

[2017-08-04 12:30:05]: 

[2017-08-04 12:30:05]: 

[2017-08-04 12:30:06]: 

[2017-08-04 12:30:06]: 

[2017-08-04 12:30:07]: 

[2017-08-04 12:30:07]: 

[2017-08-04 12:30:07]: 

[2017-08-04 12:30:08]: 

[2017-08-04 12:30:09]: 

[2017-08-04 12:30:09]: 

[2017-08-04 12:30:10]: 

[2017-08-04 12:30:10]: 

[2017-08-04 12:30:10]: 

[2017-08-04 12:30:10]: 

[2017-08-04 12:30:11]: 

[2017-08-04 12:30:11]: 

[2017-08-04 12:30:11]: 
Traceback (most recent call last):
  File "/Users/qianlong/Documents/Workspace/PyCharmProjects/xywy_ask_answer/spiders/ProcessDayUrlSpider.py", line 35, in parse
    page_numer_content = self.selector.xpath('//div[@class="club_page"]/div/text()')[-1]
AttributeError: 'NoneType' object has no attribute 'xpath'
 'NoneType' object has no attribute 'xpath'
[2017-08-04 12:30:15]: 

[2017-08-04 12:30:16]: 

[2017-08-04 12:30:16]: 

[2017-08-04 12:30:17]: 

[2017-08-04 12:30:17]: 

[2017-08-04 12:30:17]: 

[2017-08-04 12:30:18]: 

[2017-08-04 12:30:18]: 

[2017-08-04 12:30:18]: 

[2017-08-04 12:30:19]: 

[2017-08-04 12:30:19]: 

[2017-08-04 12:30:19]: 

[2017-08-04 12:30:19]: 

[2017-08-04 12:30:19]: 

[2017-08-04 12:30:19]: 

[2017-08-04 12:30:20]: 

[2017-08-04 12:30:20]: 

[2017-08-04 12:30:20]: 

[2017-08-04 12:30:21]: 

[2017-08-04 12:30:21]: 

[2017-08-04 12:30:22]: 

[2017-08-04 12:30:22]: 
Traceback (most recent call last):
  File "/Users/qianlong/Documents/Workspace/PyCharmProjects/xywy_ask_answer/spiders/ProcessDayUrlSpider.py", line 35, in parse
    page_numer_content = self.selector.xpath('//div[@class="club_page"]/div/text()')[-1]
AttributeError: 'NoneType' object has no attribute 'xpath'
 'NoneType' object has no attribute 'xpath'
[2017-08-04 12:36:57]: 

[2017-08-04 12:36:57]: 

[2017-08-04 12:36:58]: 

[2017-08-04 12:36:58]: 

[2017-08-04 12:36:58]: 

[2017-08-04 12:36:58]: 

[2017-08-04 12:36:58]: 

[2017-08-04 12:36:58]: 

[2017-08-04 12:36:59]: 

[2017-08-04 12:36:59]: 

[2017-08-04 12:36:59]: 

[2017-08-04 12:36:59]: 

[2017-08-04 12:36:59]: 

[2017-08-04 12:37:00]: 

[2017-08-04 12:37:00]: 

[2017-08-04 12:37:00]: 

[2017-08-04 12:37:00]: 

[2017-08-04 12:37:00]: 

[2017-08-04 12:37:00]: 

[2017-08-04 12:37:01]: 

[2017-08-04 12:37:01]: 

[2017-08-04 12:37:01]: 
Traceback (most recent call last):
  File "/Users/qianlong/Documents/Workspace/PyCharmProjects/xywy_ask_answer/spiders/ProcessDayUrlSpider.py", line 35, in parse
    page_numer_content = self.selector.xpath('//div[@class="club_page"]/div/text()')[-1]
AttributeError: 'NoneType' object has no attribute 'xpath'
 'NoneType' object has no attribute 'xpath'
[2017-08-04 12:37:04]: 

[2017-08-04 12:37:04]: 

[2017-08-04 12:37:05]: 

[2017-08-04 12:37:05]: 

[2017-08-04 12:37:05]: 

[2017-08-04 12:37:05]: 

[2017-08-04 12:39:04]: 

[2017-08-04 12:39:04]: 

[2017-08-04 12:39:04]: 

[2017-08-04 12:39:05]: 

[2017-08-04 12:39:06]: 

[2017-08-04 12:39:06]: 

[2017-08-04 12:39:06]: 

[2017-08-04 12:39:06]: 

[2017-08-04 12:39:06]: 

[2017-08-04 12:39:06]: 

[2017-08-04 12:39:07]: 

[2017-08-04 12:39:07]: 

[2017-08-04 12:39:07]: 

[2017-08-04 12:39:07]: 

[2017-08-04 12:39:07]: 

[2017-08-04 12:39:08]: 

[2017-08-04 12:39:08]: 

[2017-08-04 12:39:08]: 

[2017-08-04 12:39:08]: 

[2017-08-04 12:39:08]: 

[2017-08-04 12:39:09]: 

[2017-08-04 12:39:09]: 
Traceback (most recent call last):
  File "/Users/qianlong/Documents/Workspace/PyCharmProjects/xywy_ask_answer/spiders/ProcessDayUrlSpider.py", line 35, in parse
    page_numer_content = self.selector.xpath('//div[@class="club_page"]/div/text()')[-1]
AttributeError: 'NoneType' object has no attribute 'xpath'
 'NoneType' object has no attribute 'xpath'
[2017-08-04 12:39:12]: 

[2017-08-04 12:39:12]: 

[2017-08-04 12:39:12]: 

[2017-08-04 12:39:12]: 

[2017-08-04 12:39:13]: 

[2017-08-04 12:39:13]: 

[2017-08-04 12:39:13]: 

[2017-08-04 12:39:13]: 

[2017-08-04 12:39:13]: 

[2017-08-04 12:39:14]: 

[2017-08-04 12:39:14]: 

[2017-08-04 12:39:14]: 

[2017-08-04 12:39:14]: 

[2017-08-04 12:39:14]: 

[2017-08-04 12:39:15]: 

[2017-08-04 12:39:15]: 

[2017-08-04 12:39:15]: 

[2017-08-04 12:39:15]: 

[2017-08-04 12:39:15]: 

[2017-08-04 13:04:14]: 

[2017-08-04 13:04:14]: 

[2017-08-04 13:04:14]: 

[2017-08-04 13:04:14]: 

[2017-08-04 13:04:14]: 

[2017-08-04 13:04:14]: 

[2017-08-04 13:04:15]: 

[2017-08-04 13:04:15]: 

[2017-08-04 13:04:15]: 

[2017-08-04 13:04:15]: 

[2017-08-04 13:04:15]: 

[2017-08-04 13:04:16]: 

[2017-08-04 13:04:16]: 

[2017-08-04 13:04:16]: 

[2017-08-04 13:04:16]: 

[2017-08-04 13:04:16]: 

[2017-08-04 13:04:17]: 

[2017-08-04 13:04:17]: 

[2017-08-04 13:04:17]: 

[2017-08-04 13:04:17]: 

[2017-08-04 13:04:17]: 

[2017-08-04 13:04:17]: 
Traceback (most recent call last):
  File "/Users/qianlong/Documents/Workspace/PyCharmProjects/xywy_ask_answer/spiders/ProcessDayUrlSpider.py", line 35, in parse
    page_numer_content = self.selector.xpath('//div[@class="club_page"]/div/text()')[-1]
AttributeError: 'NoneType' object has no attribute 'xpath'
 'NoneType' object has no attribute 'xpath'
[2017-08-04 13:05:38]: 

[2017-08-04 13:05:38]: 

[2017-08-04 13:05:38]: 

[2017-08-04 13:05:39]: 

[2017-08-04 13:05:39]: 

[2017-08-04 13:05:39]: 

[2017-08-04 13:05:39]: 

[2017-08-04 13:05:39]: 

[2017-08-04 13:05:40]: 

[2017-08-04 13:05:40]: 

[2017-08-04 13:05:40]: 

[2017-08-04 13:05:40]: 

[2017-08-04 13:05:40]: 

[2017-08-04 13:05:41]: 

[2017-08-04 13:05:41]: 

[2017-08-04 13:05:41]: 

[2017-08-04 13:41:39]: 

[2017-08-04 13:41:39]: 

[2017-08-04 13:41:39]: 

[2017-08-04 13:41:39]: 

[2017-08-04 13:41:40]: 

[2017-08-04 13:41:40]: 

[2017-08-04 13:41:40]: 

[2017-08-04 13:41:40]: 

[2017-08-04 13:41:40]: 

[2017-08-04 13:41:40]: 

[2017-08-04 13:41:41]: 

[2017-08-04 13:41:41]: 

[2017-08-04 13:41:41]: 

[2017-08-04 13:41:41]: 

[2017-08-04 13:41:41]: 

[2017-08-04 13:42:38]: 

[2017-08-04 13:42:38]: 

[2017-08-04 13:42:39]: 

[2017-08-04 13:42:39]: 

[2017-08-04 13:42:39]: 

[2017-08-04 13:42:39]: 

[2017-08-04 13:42:39]: 

[2017-08-04 13:42:40]: 

[2017-08-04 13:42:40]: 

[2017-08-04 13:42:40]: 

[2017-08-04 13:42:40]: 

[2017-08-04 13:42:40]: 

[2017-08-04 13:42:41]: 

[2017-08-04 13:42:41]: 

[2017-08-04 13:42:41]: 

[2017-08-04 13:42:41]: 

[2017-08-04 13:42:41]: 

[2017-08-04 13:42:41]: 

[2017-08-04 13:42:42]: 

[2017-08-04 13:42:42]: 

[2017-08-04 13:42:42]: 

[2017-08-04 13:42:42]: 
Traceback (most recent call last):
  File "/Users/qianlong/Documents/Workspace/PyCharmProjects/xywy_ask_answer/spiders/ProcessDayUrlSpider.py", line 35, in parse
    page_numer_content = self.selector.xpath('//div[@class="club_page"]/div/text()')[-1]
AttributeError: 'NoneType' object has no attribute 'xpath'
 'NoneType' object has no attribute 'xpath'
[2017-08-04 13:42:45]: 

[2017-08-04 13:42:46]: 

[2017-08-04 13:42:46]: 

[2017-08-04 13:42:46]: 

[2017-08-04 13:42:46]: 

[2017-08-04 13:42:46]: 

[2017-08-04 13:42:46]: 

[2017-08-04 13:42:47]: 

[2017-08-04 13:42:47]: 

[2017-08-04 13:42:47]: 

[2017-08-04 13:42:47]: 

[2017-08-04 13:42:47]: 

[2017-08-04 13:42:48]: 

[2017-08-04 13:42:48]: 

[2017-08-04 13:42:48]: 

[2017-08-04 13:42:48]: 

[2017-08-04 13:42:49]: 

[2017-08-04 13:42:49]: 

[2017-08-04 13:42:50]: 

[2017-08-04 13:42:50]: 

[2017-08-04 13:42:50]: 

[2017-08-04 13:42:50]: 
Traceback (most recent call last):
  File "/Users/qianlong/Documents/Workspace/PyCharmProjects/xywy_ask_answer/spiders/ProcessDayUrlSpider.py", line 35, in parse
    page_numer_content = self.selector.xpath('//div[@class="club_page"]/div/text()')[-1]
AttributeError: 'NoneType' object has no attribute 'xpath'
 'NoneType' object has no attribute 'xpath'
[2017-08-04 13:43:47]: 

[2017-08-04 13:43:48]: 

[2017-08-04 13:43:48]: 

[2017-08-04 13:43:48]: 

[2017-08-04 13:43:48]: 

[2017-08-04 13:43:48]: 

[2017-08-04 13:43:49]: 

[2017-08-04 13:43:49]: 

[2017-08-04 13:43:49]: 

[2017-08-04 13:43:49]: 

[2017-08-04 13:43:49]: 

[2017-08-04 13:43:50]: 

[2017-08-04 13:43:50]: 

[2017-08-04 13:43:50]: 

[2017-08-04 13:43:50]: 

[2017-08-04 13:44:30]: 

[2017-08-04 13:44:30]: 

[2017-08-04 13:44:30]: 

[2017-08-04 13:44:30]: 

[2017-08-04 13:44:31]: 

[2017-08-04 13:44:31]: 

[2017-08-04 13:53:02]: 

[2017-08-04 13:53:02]: 

[2017-08-04 13:53:03]: 

[2017-08-04 13:53:04]: 

[2017-08-04 13:53:04]: 

[2017-08-04 13:53:04]: 

[2017-08-04 13:53:04]: 

[2017-08-04 13:53:04]: 

[2017-08-04 13:53:05]: 

[2017-08-04 13:53:06]: 

[2017-08-04 13:53:06]: 

[2017-08-04 13:53:06]: 

[2017-08-04 13:53:06]: 

[2017-08-04 13:53:07]: 

[2017-08-04 13:53:08]: 

[2017-08-04 13:53:08]: 

[2017-08-04 13:53:09]: 

[2017-08-04 13:53:09]: 

[2017-08-04 13:53:10]: 

[2017-08-04 13:53:11]: 

[2017-08-04 13:53:11]: 

[2017-08-04 13:53:11]: 
Traceback (most recent call last):
  File "/Users/qianlong/Documents/Workspace/PyCharmProjects/xywy_ask_answer/spiders/ProcessDayUrlSpider.py", line 35, in parse
    page_numer_content = self.selector.xpath('//div[@class="club_page"]/div/text()')[-1]
AttributeError: 'NoneType' object has no attribute 'xpath'
 'NoneType' object has no attribute 'xpath'
[2017-08-04 13:53:14]: 

[2017-08-04 13:53:15]: 

[2017-08-04 13:53:15]: 

[2017-08-04 13:53:15]: 

[2017-08-04 13:53:15]: 

[2017-08-04 13:53:16]: 

[2017-08-04 13:53:18]: 

[2017-08-04 13:53:18]: 

[2017-08-04 13:53:19]: 

[2017-08-04 13:53:19]: 

[2017-08-04 13:53:19]: 

[2017-08-04 13:53:19]: 

[2017-08-04 13:53:20]: 

[2017-08-04 13:53:20]: 

[2017-08-04 13:53:20]: 

[2017-08-04 13:53:20]: 

[2017-08-04 13:53:20]: 

[2017-08-04 13:53:21]: 

[2017-08-04 13:53:21]: 

[2017-08-04 13:53:21]: 

[2017-08-04 13:53:21]: 

[2017-08-04 13:53:21]: 
Traceback (most recent call last):
  File "/Users/qianlong/Documents/Workspace/PyCharmProjects/xywy_ask_answer/spiders/ProcessDayUrlSpider.py", line 35, in parse
    page_numer_content = self.selector.xpath('//div[@class="club_page"]/div/text()')[-1]
AttributeError: 'NoneType' object has no attribute 'xpath'
 'NoneType' object has no attribute 'xpath'
[2017-08-04 13:53:24]: 

[2017-08-04 13:53:25]: 

[2017-08-04 13:53:25]: 

[2017-08-04 13:53:25]: 

[2017-08-04 13:53:26]: 

[2017-08-04 13:53:27]: 

[2017-08-04 13:53:27]: 

[2017-08-04 13:53:28]: 

[2017-08-04 13:53:46]: 

[2017-08-04 13:53:49]: 

[2017-08-04 13:53:50]: 

[2017-08-04 13:53:50]: 

